2020-03-20 09:31:09,736 ERROR: Exception on /favicon.ico [GET] [in c:\users\jhn\appdata\local\programs\python\python37-32\lib\site-packages\flask\app.py:1761]
Traceback (most recent call last):
  File "c:\users\jhn\appdata\local\programs\python\python37-32\lib\site-packages\flask\app.py", line 1813, in full_dispatch_request
    rv = self.dispatch_request()
  File "c:\users\jhn\appdata\local\programs\python\python37-32\lib\site-packages\flask\app.py", line 1791, in dispatch_request
    self.raise_routing_exception(req)
  File "c:\users\jhn\appdata\local\programs\python\python37-32\lib\site-packages\flask\app.py", line 1774, in raise_routing_exception
    raise request.routing_exception
  File "c:\users\jhn\appdata\local\programs\python\python37-32\lib\site-packages\flask\ctx.py", line 336, in match_request
    self.url_adapter.match(return_rule=True)
  File "c:\users\jhn\appdata\local\programs\python\python37-32\lib\site-packages\werkzeug\routing.py", line 1784, in match
    raise NotFound()
werkzeug.exceptions.NotFound: 404 Not Found: The requested URL was not found on the server. If you entered the URL manually please check your spelling and try again.

During handling of the above exception, another exception occurred:

Traceback (most recent call last):
  File "c:\users\jhn\appdata\local\programs\python\python37-32\lib\site-packages\flask\app.py", line 2292, in wsgi_app
    response = self.full_dispatch_request()
  File "c:\users\jhn\appdata\local\programs\python\python37-32\lib\site-packages\flask\app.py", line 1815, in full_dispatch_request
    rv = self.handle_user_exception(e)
  File "c:\users\jhn\appdata\local\programs\python\python37-32\lib\site-packages\flask\app.py", line 1713, in handle_user_exception
    return self.handle_http_exception(e)
  File "c:\users\jhn\appdata\local\programs\python\python37-32\lib\site-packages\flask\app.py", line 1644, in handle_http_exception
    return handler(e)
  File "C:\Users\JHN\Desktop\Online_Calendar\app\errors\handlers.py", line 8, in not_found_error
    return render_template('errors/404.html'), 404
  File "c:\users\jhn\appdata\local\programs\python\python37-32\lib\site-packages\flask\templating.py", line 135, in render_template
    context, ctx.app)
  File "c:\users\jhn\appdata\local\programs\python\python37-32\lib\site-packages\flask\templating.py", line 117, in _render
    rv = template.render(context)
  File "c:\users\jhn\appdata\local\programs\python\python37-32\lib\site-packages\jinja2\asyncsupport.py", line 76, in render
    return original_render(self, *args, **kwargs)
  File "c:\users\jhn\appdata\local\programs\python\python37-32\lib\site-packages\jinja2\environment.py", line 1008, in render
    return self.environment.handle_exception(exc_info, True)
  File "c:\users\jhn\appdata\local\programs\python\python37-32\lib\site-packages\jinja2\environment.py", line 780, in handle_exception
    reraise(exc_type, exc_value, tb)
  File "c:\users\jhn\appdata\local\programs\python\python37-32\lib\site-packages\jinja2\_compat.py", line 37, in reraise
    raise value.with_traceback(tb)
  File "C:\Users\JHN\Desktop\Online_Calendar\app\templates\errors\404.html", line 1, in top-level template code
    {% extends "base.html" %}
  File "C:\Users\JHN\Desktop\Online_Calendar\app\templates\base.html", line 1, in top-level template code
    {% extends 'bootstrap/base.html' %}
  File "c:\users\jhn\appdata\local\programs\python\python37-32\lib\site-packages\flask_bootstrap\templates\bootstrap\base.html", line 1, in top-level template code
    {% block doc -%}
  File "c:\users\jhn\appdata\local\programs\python\python37-32\lib\site-packages\flask_bootstrap\templates\bootstrap\base.html", line 4, in block "doc"
    {%- block html %}
  File "c:\users\jhn\appdata\local\programs\python\python37-32\lib\site-packages\flask_bootstrap\templates\bootstrap\base.html", line 20, in block "html"
    {% block body -%}
  File "c:\users\jhn\appdata\local\programs\python\python37-32\lib\site-packages\flask_bootstrap\templates\bootstrap\base.html", line 23, in block "body"
    {% block content -%}
  File "C:\Users\JHN\Desktop\Online_Calendar\app\templates\base.html", line 48, in block "content"
    {% block app_content %}{% endblock %}
  File "C:\Users\JHN\Desktop\Online_Calendar\app\templates\errors\404.html", line 5, in block "app_content"
    <p><a href="{{ url_for('index') }}">Back</a></p>
  File "c:\users\jhn\appdata\local\programs\python\python37-32\lib\site-packages\flask\helpers.py", line 356, in url_for
    return appctx.app.handle_url_build_error(error, endpoint, values)
  File "c:\users\jhn\appdata\local\programs\python\python37-32\lib\site-packages\flask\app.py", line 2061, in handle_url_build_error
    reraise(exc_type, exc_value, tb)
  File "c:\users\jhn\appdata\local\programs\python\python37-32\lib\site-packages\flask\_compat.py", line 35, in reraise
    raise value
  File "c:\users\jhn\appdata\local\programs\python\python37-32\lib\site-packages\flask\helpers.py", line 345, in url_for
    force_external=external)
  File "c:\users\jhn\appdata\local\programs\python\python37-32\lib\site-packages\werkzeug\routing.py", line 2005, in build
    raise BuildError(endpoint, values, method, self)
werkzeug.routing.BuildError: Could not build url for endpoint 'index'. Did you mean 'main.index' instead?
